Workbook

Sheet Прайс-лист
A1: ПЧК — B2B прайс-лист и выбор позиций для заказа
A2: Поставьте количество в колонке «Кол-во в заказ». Выбранные позиции автоматически попадут на лист «Бланк заказа». В макете уже заполнены 3 тестовые строки — их можно удалить.
A4: Уровень цен для расчета | B4: Базовый
A5: Предварительный уровень по сумме | B5: =IF('Бланк заказа'!$G$5<20000,"Ниже минимума",IF('Бланк заказа'!$G$5<50000,"Базовый",IF('Бланк заказа'!$G$5<150000,"Опт",IF('Бланк заказа'!$G$5<300000,"Опт+",IF('Бланк заказа'!$G$5<500000,"Партнер","Ключевой партнер"))))) -> Ниже минимума
A6: Проверка уровня | B6: =IF(B4=B5,"Уровень соответствует сумме","Проверьте: по сумме заказа предварительный уровень — "&B5) -> Проверьте: по сумме заказа предварительный уровень — Ниже минимума
A7: Важно | B7: Итоговые цены, наличие, бонусы и специальные условия подтверждаются менеджером. Прайс-лист не является публичной офертой.
A10: Категория | B10: Артикул | C10: Наименование | D10: Краткое описание | E10: Фасовка | F10: Ед. изм. | G10: Мин. партия | H10: Кратность | I10: Базовый | J10: Опт | K10: Опт+ | L10: Партнер | M10: Ключевой партнер | N10: Статус | O10: Комментарий | P10: Кол-во в заказ | Q10: Комментарий к заказу | R10: Цена для расчета | S10: Сумма без НДС | T10: № в заказе
R11: =IF($P11>0,CHOOSE(MATCH($B$4,'Служебный лист'!$A$4:$A$8,0),I11,J11,K11,L11,M11),"") | S11: =IFERROR($P11*$R11,0) -> 0 | T11: =IF($P11>0,COUNTIF($P$11:P11,">0"),"")
R12: =IF($P12>0,CHOOSE(MATCH($B$4,'Служебный лист'!$A$4:$A$8,0),I12,J12,K12,L12,M12),"") | S12: =IFERROR($P12*$R12,0) -> 0 | T12: =IF($P12>0,COUNTIF($P$11:P12,">0"),"")
R13: =IF($P13>0,CHOOSE(MATCH($B$4,'Служебный лист'!$A$4:$A$8,0),I13,J13,K13,L13,M13),"") | S13: =IFERROR($P13*$R13,0) -> 0 | T13: =IF($P13>0,COUNTIF($P$11:P13,">0"),"")
R14: =IF($P14>0,CHOOSE(MATCH($B$4,'Служебный лист'!$A$4:$A$8,0),I14,J14,K14,L14,M14),"") | S14: =IFERROR($P14*$R14,0) -> 0 | T14: =IF($P14>0,COUNTIF($P$11:P14,">0"),"")
R15: =IF($P15>0,CHOOSE(MATCH($B$4,'Служебный лист'!$A$4:$A$8,0),I15,J15,K15,L15,M15),"") | S15: =IFERROR($P15*$R15,0) -> 0 | T15: =IF($P15>0,COUNTIF($P$11:P15,">0"),"")
R16: =IF($P16>0,CHOOSE(MATCH($B$4,'Служебный лист'!$A$4:$A$8,0),I16,J16,K16,L16,M16),"") | S16: =IFERROR($P16*$R16,0) -> 0 | T16: =IF($P16>0,COUNTIF($P$11:P16,">0"),"")
R17: =IF($P17>0,CHOOSE(MATCH($B$4,'Служебный лист'!$A$4:$A$8,0),I17,J17,K17,L17,M17),"") | S17: =IFERROR($P17*$R17,0) -> 0 | T17: =IF($P17>0,COUNTIF($P$11:P17,">0"),"")
R18: =IF($P18>0,CHOOSE(MATCH($B$4,'Служебный лист'!$A$4:$A$8,0),I18,J18,K18,L18,M18),"") | S18: =IFERROR($P18*$R18,0) -> 0 | T18: =IF($P18>0,COUNTIF($P$11:P18,">0"),"")
R19: =IF($P19>0,CHOOSE(MATCH($B$4,'Служебный лист'!$A$4:$A$8,0),I19,J19,K19,L19,M19),"") | S19: =IFERROR($P19*$R19,0) -> 0 | T19: =IF($P19>0,COUNTIF($P$11:P19,">0"),"")
R20: =IF($P20>0,CHOOSE(MATCH($B$4,'Служебный лист'!$A$4:$A$8,0),I20,J20,K20,L20,M20),"") | S20: =IFERROR($P20*$R20,0) -> 0 | T20: =IF($P20>0,COUNTIF($P$11:P20,">0"),"")
R21: =IF($P21>0,CHOOSE(MATCH($B$4,'Служебный лист'!$A$4:$A$8,0),I21,J21,K21,L21,M21),"") | S21: =IFERROR($P21*$R21,0) -> 0 | T21: =IF($P21>0,COUNTIF($P$11:P21,">0"),"")
R22: =IF($P22>0,CHOOSE(MATCH($B$4,'Служебный лист'!$A$4:$A$8,0),I22,J22,K22,L22,M22),"") | S22: =IFERROR($P22*$R22,0) -> 0 | T22: =IF($P22>0,COUNTIF($P$11:P22,">0"),"")
... R310: =IF($P310>0,CHOOSE(MATCH($B$4,'Служебный лист'!$A$4:$A$8,0),I310,J310,K310,L310,M310),"") | S310: =IFERROR($P310*$R310,0) -> 0 | T310: =IF($P310>0,COUNTIF($P$11:P310,">0"),"")

Sheet Бланк заказа
A1: Бланк заказа — автоматически собирается из листа «Прайс-лист»
A2: Заполните количество на листе «Прайс-лист». В этот бланк автоматически попадают только выбранные позиции. В макете для проверки уже есть 3 тестовые позиции.
A4: Дата заказа | B4: 46152 | F4: Итог заказа
A5: Название клиента | C5: Город | F5: Сумма без НДС | G5: =SUM(I16:I315) -> 0
A6: Контактное лицо | C6: Телефон / email | F6: НДС | G6: =G5*'Служебный лист'!$B$1 -> 0
A7: Менеджер | C7: Условия оплаты | D7: 100% предоплата / по договору | F7: Итого с НДС | G7: =G5+G6 -> 0
A8: Комментарий к заказу | F8: Количество выбранных SKU | G8: =COUNTIF(H16:H315,">0") -> 0
F9: Текущий уровень | G9: =IF(G5<20000,"Ниже минимума",IF(G5<50000,"Базовый",IF(G5<150000,"Опт",IF(G5<300000,"Опт+",IF(G5<500000,"Партнер","Ключевой партнер"))))) -> Ниже минимума
F10: Следующий порог | G10: =IF(G5<20000,20000,IF(G5<50000,50000,IF(G5<150000,150000,IF(G5<300000,300000,IF(G5<500000,500000,""))))) -> 20000
F11: До следующего уровня осталось | G11: =IF(G10="",0,MAX(G10-G5,0)) -> 20000
F12: Проверка минимального заказа | G12: =IF(G5<20000,"Минимальная сумма заказа — 20 000 ₽ без НДС","Заказ соответствует минимальной сумме") -> Минимальная сумма заказа — 20 000 ₽ без НДС
F13: Возможные партнерские преимущества | G13: =IF(G5<20000,"Доберите заказ до минимальной суммы",IF(G5>=500000,"Возможны индивидуальные условия и ретробонус",IF(G5>=300000,"Возможны партнерские условия и ретробонус",IF(G5>=150000,"Возможны образцы новинок и расширенные условия",IF(G8>=20,"Возможен бонус за ширину ассортимента","Обсудите с менеджером условия регулярных закупок"))))) -> Доберите заказ до минимальной суммы
A15: № | B15: Категория | C15: Артикул | D15: Наименование | E15: Фасовка | F15: Ед. изм. | G15: Цена без НДС | H15: Кол-во | I15: Сумма без НДС | J15: Комментарий
A16: =IFERROR(IF(INDEX('Прайс-лист'!$T$11:$T$310,MATCH(ROWS($A$16:A16),'Прайс-лист'!$T$11:$T$310,0))="","",ROWS($A$16:A16)),"") | B16: =IFERROR(INDEX('Прайс-лист'!$A$11:$A$310,MATCH(ROWS($A$16:A16),'Прайс-лист'!$T$11:$T$310,0)),"") | C16: =IFERROR(INDEX('Прайс-лист'!$B$11:$B$310,MATCH(ROWS($A$16:A16),'Прайс-лист'!$T$11:$T$310,0)),"") | D16: =IFERROR(INDEX('Прайс-лист'!$C$11:$C$310,MATCH(ROWS($A$16:A16),'Прайс-лист'!$T$11:$T$310,0)),"") | E16: =IFERROR(INDEX('Прайс-лист'!$E$11:$E$310,MATCH(ROWS($A$16:A16),'Прайс-лист'!$T$11:$T$310,0)),"") | F16: =IFERROR(INDEX('Прайс-лист'!$F$11:$F$310,MATCH(ROWS($A$16:A16),'Прайс-лист'!$T$11:$T$310,0)),"") | G16: =IFERROR(INDEX('Прайс-лист'!$R$11:$R$310,MATCH(ROWS($A$16:A16),'Прайс-лист'!$T$11:$T$310,0)),"") | H16: =IFERROR(INDEX('Прайс-лист'!$P$11:$P$310,MATCH(ROWS($A$16:A16),'Прайс-лист'!$T$11:$T$310,0)),"") | I16: =IFERROR(INDEX('Прайс-лист'!$S$11:$S$310,MATCH(ROWS($A$16:A16),'Прайс-лист'!$T$11:$T$310,0)),"") | J16: =IFERROR(INDEX('Прайс-лист'!$Q$11:$Q$310,MATCH(ROWS($A$16:A16),'Прайс-лист'!$T$11:$T$310,0)),"")
A17: =IFERROR(IF(INDEX('Прайс-лист'!$T$11:$T$310,MATCH(ROWS($A$16:A17),'Прайс-лист'!$T$11:$T$310,0))="","",ROWS($A$16:A17)),"") | B17: =IFERROR(INDEX('Прайс-лист'!$A$11:$A$310,MATCH(ROWS($A$16:A17),'Прайс-лист'!$T$11:$T$310,0)),"") | C17: =IFERROR(INDEX('Прайс-лист'!$B$11:$B$310,MATCH(ROWS($A$16:A17),'Прайс-лист'!$T$11:$T$310,0)),"") | D17: =IFERROR(INDEX('Прайс-лист'!$C$11:$C$310,MATCH(ROWS($A$16:A17),'Прайс-лист'!$T$11:$T$310,0)),"") | E17: =IFERROR(INDEX('Прайс-лист'!$E$11:$E$310,MATCH(ROWS($A$16:A17),'Прайс-лист'!$T$11:$T$310,0)),"") | F17: =IFERROR(INDEX('Прайс-лист'!$F$11:$F$310,MATCH(ROWS($A$16:A17),'Прайс-лист'!$T$11:$T$310,0)),"") | G17: =IFERROR(INDEX('Прайс-лист'!$R$11:$R$310,MATCH(ROWS($A$16:A17),'Прайс-лист'!$T$11:$T$310,0)),"") | H17: =IFERROR(INDEX('Прайс-лист'!$P$11:$P$310,MATCH(ROWS($A$16:A17),'Прайс-лист'!$T$11:$T$310,0)),"") | I17: =IFERROR(INDEX('Прайс-лист'!$S$11:$S$310,MATCH(ROWS($A$16:A17),'Прайс-лист'!$T$11:$T$310,0)),"") | J17: =IFERROR(INDEX('Прайс-лист'!$Q$11:$Q$310,MATCH(ROWS($A$16:A17),'Прайс-лист'!$T$11:$T$310,0)),"")
A18: =IFERROR(IF(INDEX('Прайс-лист'!$T$11:$T$310,MATCH(ROWS($A$16:A18),'Прайс-лист'!$T$11:$T$310,0))="","",ROWS($A$16:A18)),"") | B18: =IFERROR(INDEX('Прайс-лист'!$A$11:$A$310,MATCH(ROWS($A$16:A18),'Прайс-лист'!$T$11:$T$310,0)),"") | C18: =IFERROR(INDEX('Прайс-лист'!$B$11:$B$310,MATCH(ROWS($A$16:A18),'Прайс-лист'!$T$11:$T$310,0)),"") | D18: =IFERROR(INDEX('Прайс-лист'!$C$11:$C$310,MATCH(ROWS($A$16:A18),'Прайс-лист'!$T$11:$T$310,0)),"") | E18: =IFERROR(INDEX('Прайс-лист'!$E$11:$E$310,MATCH(ROWS($A$16:A18),'Прайс-лист'!$T$11:$T$310,0)),"") | F18: =IFERROR(INDEX('Прайс-лист'!$F$11:$F$310,MATCH(ROWS($A$16:A18),'Прайс-лист'!$T$11:$T$310,0)),"") | G18: =IFERROR(INDEX('Прайс-лист'!$R$11:$R$310,MATCH(ROWS($A$16:A18),'Прайс-лист'!$T$11:$T$310,0)),"") | H18: =IFERROR(INDEX('Прайс-лист'!$P$11:$P$310,MATCH(ROWS($A$16:A18),'Прайс-лист'!$T$11:$T$310,0)),"") | I18: =IFERROR(INDEX('Прайс-лист'!$S$11:$S$310,MATCH(ROWS($A$16:A18),'Прайс-лист'!$T$11:$T$310,0)),"") | J18: =IFERROR(INDEX('Прайс-лист'!$Q$11:$Q$310,MATCH(ROWS($A$16:A18),'Прайс-лист'!$T$11:$T$310,0)),"")
A19: =IFERROR(IF(INDEX('Прайс-лист'!$T$11:$T$310,MATCH(ROWS($A$16:A19),'Прайс-лист'!$T$11:$T$310,0))="","",ROWS($A$16:A19)),"") | B19: =IFERROR(INDEX('Прайс-лист'!$A$11:$A$310,MATCH(ROWS($A$16:A19),'Прайс-лист'!$T$11:$T$310,0)),"") | C19: =IFERROR(INDEX('Прайс-лист'!$B$11:$B$310,MATCH(ROWS($A$16:A19),'Прайс-лист'!$T$11:$T$310,0)),"") | D19: =IFERROR(INDEX('Прайс-лист'!$C$11:$C$310,MATCH(ROWS($A$16:A19),'Прайс-лист'!$T$11:$T$310,0)),"") | E19: =IFERROR(INDEX('Прайс-лист'!$E$11:$E$310,MATCH(ROWS($A$16:A19),'Прайс-лист'!$T$11:$T$310,0)),"") | F19: =IFERROR(INDEX('Прайс-лист'!$F$11:$F$310,MATCH(ROWS($A$16:A19),'Прайс-лист'!$T$11:$T$310,0)),"") | G19: =IFERROR(INDEX('Прайс-лист'!$R$11:$R$310,MATCH(ROWS($A$16:A19),'Прайс-лист'!$T$11:$T$310,0)),"") | H19: =IFERROR(INDEX('Прайс-лист'!$P$11:$P$310,MATCH(ROWS($A$16:A19),'Прайс-лист'!$T$11:$T$310,0)),"") | I19: =IFERROR(INDEX('Прайс-лист'!$S$11:$S$310,MATCH(ROWS($A$16:A19),'Прайс-лист'!$T$11:$T$310,0)),"") | J19: =IFERROR(INDEX('Прайс-лист'!$Q$11:$Q$310,MATCH(ROWS($A$16:A19),'Прайс-лист'!$T$11:$T$310,0)),"")
A20: =IFERROR(IF(INDEX('Прайс-лист'!$T$11:$T$310,MATCH(ROWS($A$16:A20),'Прайс-лист'!$T$11:$T$310,0))="","",ROWS($A$16:A20)),"") | B20: =IFERROR(INDEX('Прайс-лист'!$A$11:$A$310,MATCH(ROWS($A$16:A20),'Прайс-лист'!$T$11:$T$310,0)),"") | C20: =IFERROR(INDEX('Прайс-лист'!$B$11:$B$310,MATCH(ROWS($A$16:A20),'Прайс-лист'!$T$11:$T$310,0)),"") | D20: =IFERROR(INDEX('Прайс-лист'!$C$11:$C$310,MATCH(ROWS($A$16:A20),'Прайс-лист'!$T$11:$T$310,0)),"") | E20: =IFERROR(INDEX('Прайс-лист'!$E$11:$E$310,MATCH(ROWS($A$16:A20),'Прайс-лист'!$T$11:$T$310,0)),"") | F20: =IFERROR(INDEX('Прайс-лист'!$F$11:$F$310,MATCH(ROWS($A$16:A20),'Прайс-лист'!$T$11:$T$310,0)),"") | G20: =IFERROR(INDEX('Прайс-лист'!$R$11:$R$310,MATCH(ROWS($A$16:A20),'Прайс-лист'!$T$11:$T$310,0)),"") | H20: =IFERROR(INDEX('Прайс-лист'!$P$11:$P$310,MATCH(ROWS($A$16:A20),'Прайс-лист'!$T$11:$T$310,0)),"") | I20: =IFERROR(INDEX('Прайс-лист'!$S$11:$S$310,MATCH(ROWS($A$16:A20),'Прайс-лист'!$T$11:$T$310,0)),"") | J20: =IFERROR(INDEX('Прайс-лист'!$Q$11:$Q$310,MATCH(ROWS($A$16:A20),'Прайс-лист'!$T$11:$T$310,0)),"")
A21: =IFERROR(IF(INDEX('Прайс-лист'!$T$11:$T$310,MATCH(ROWS($A$16:A21),'Прайс-лист'!$T$11:$T$310,0))="","",ROWS($A$16:A21)),"") | B21: =IFERROR(INDEX('Прайс-лист'!$A$11:$A$310,MATCH(ROWS($A$16:A21),'Прайс-лист'!$T$11:$T$310,0)),"") | C21: =IFERROR(INDEX('Прайс-лист'!$B$11:$B$310,MATCH(ROWS($A$16:A21),'Прайс-лист'!$T$11:$T$310,0)),"") | D21: =IFERROR(INDEX('Прайс-лист'!$C$11:$C$310,MATCH(ROWS($A$16:A21),'Прайс-лист'!$T$11:$T$310,0)),"") | E21: =IFERROR(INDEX('Прайс-лист'!$E$11:$E$310,MATCH(ROWS($A$16:A21),'Прайс-лист'!$T$11:$T$310,0)),"") | F21: =IFERROR(INDEX('Прайс-лист'!$F$11:$F$310,MATCH(ROWS($A$16:A21),'Прайс-лист'!$T$11:$T$310,0)),"") | G21: =IFERROR(INDEX('Прайс-лист'!$R$11:$R$310,MATCH(ROWS($A$16:A21),'Прайс-лист'!$T$11:$T$310,0)),"") | H21: =IFERROR(INDEX('Прайс-лист'!$P$11:$P$310,MATCH(ROWS($A$16:A21),'Прайс-лист'!$T$11:$T$310,0)),"") | I21: =IFERROR(INDEX('Прайс-лист'!$S$11:$S$310,MATCH(ROWS($A$16:A21),'Прайс-лист'!$T$11:$T$310,0)),"") | J21: =IFERROR(INDEX('Прайс-лист'!$Q$11:$Q$310,MATCH(ROWS($A$16:A21),'Прайс-лист'!$T$11:$T$310,0)),"")
A22: =IFERROR(IF(INDEX('Прайс-лист'!$T$11:$T$310,MATCH(ROWS($A$16:A22),'Прайс-лист'!$T$11:$T$310,0))="","",ROWS($A$16:A22)),"") | B22: =IFERROR(INDEX('Прайс-лист'!$A$11:$A$310,MATCH(ROWS($A$16:A22),'Прайс-лист'!$T$11:$T$310,0)),"") | C22: =IFERROR(INDEX('Прайс-лист'!$B$11:$B$310,MATCH(ROWS($A$16:A22),'Прайс-лист'!$T$11:$T$310,0)),"") | D22: =IFERROR(INDEX('Прайс-лист'!$C$11:$C$310,MATCH(ROWS($A$16:A22),'Прайс-лист'!$T$11:$T$310,0)),"") | E22: =IFERROR(INDEX('Прайс-лист'!$E$11:$E$310,MATCH(ROWS($A$16:A22),'Прайс-лист'!$T$11:$T$310,0)),"") | F22: =IFERROR(INDEX('Прайс-лист'!$F$11:$F$310,MATCH(ROWS($A$16:A22),'Прайс-лист'!$T$11:$T$310,0)),"") | G22: =IFERROR(INDEX('Прайс-лист'!$R$11:$R$310,MATCH(ROWS($A$16:A22),'Прайс-лист'!$T$11:$T$310,0)),"") | H22: =IFERROR(INDEX('Прайс-лист'!$P$11:$P$310,MATCH(ROWS($A$16:A22),'Прайс-лист'!$T$11:$T$310,0)),"") | I22: =IFERROR(INDEX('Прайс-лист'!$S$11:$S$310,MATCH(ROWS($A$16:A22),'Прайс-лист'!$T$11:$T$310,0)),"") | J22: =IFERROR(INDEX('Прайс-лист'!$Q$11:$Q$310,MATCH(ROWS($A$16:A22),'Прайс-лист'!$T$11:$T$310,0)),"")
A23: =IFERROR(IF(INDEX('Прайс-лист'!$T$11:$T$310,MATCH(ROWS($A$16:A23),'Прайс-лист'!$T$11:$T$310,0))="","",ROWS($A$16:A23)),"") | B23: =IFERROR(INDEX('Прайс-лист'!$A$11:$A$310,MATCH(ROWS($A$16:A23),'Прайс-лист'!$T$11:$T$310,0)),"") | C23: =IFERROR(INDEX('Прайс-лист'!$B$11:$B$310,MATCH(ROWS($A$16:A23),'Прайс-лист'!$T$11:$T$310,0)),"") | D23: =IFERROR(INDEX('Прайс-лист'!$C$11:$C$310,MATCH(ROWS($A$16:A23),'Прайс-лист'!$T$11:$T$310,0)),"") | E23: =IFERROR(INDEX('Прайс-лист'!$E$11:$E$310,MATCH(ROWS($A$16:A23),'Прайс-лист'!$T$11:$T$310,0)),"") | F23: =IFERROR(INDEX('Прайс-лист'!$F$11:$F$310,MATCH(ROWS($A$16:A23),'Прайс-лист'!$T$11:$T$310,0)),"") | G23: =IFERROR(INDEX('Прайс-лист'!$R$11:$R$310,MATCH(ROWS($A$16:A23),'Прайс-лист'!$T$11:$T$310,0)),"") | H23: =IFERROR(INDEX('Прайс-лист'!$P$11:$P$310,MATCH(ROWS($A$16:A23),'Прайс-лист'!$T$11:$T$310,0)),"") | I23: =IFERROR(INDEX('Прайс-лист'!$S$11:$S$310,MATCH(ROWS($A$16:A23),'Прайс-лист'!$T$11:$T$310,0)),"") | J23: =IFERROR(INDEX('Прайс-лист'!$Q$11:$Q$310,MATCH(ROWS($A$16:A23),'Прайс-лист'!$T$11:$T$310,0)),"")
A24: =IFERROR(IF(INDEX('Прайс-лист'!$T$11:$T$310,MATCH(ROWS($A$16:A24),'Прайс-лист'!$T$11:$T$310,0))="","",ROWS($A$16:A24)),"") | B24: =IFERROR(INDEX('Прайс-лист'!$A$11:$A$310,MATCH(ROWS($A$16:A24),'Прайс-лист'!$T$11:$T$310,0)),"") | C24: =IFERROR(INDEX('Прайс-лист'!$B$11:$B$310,MATCH(ROWS($A$16:A24),'Прайс-лист'!$T$11:$T$310,0)),"") | D24: =IFERROR(INDEX('Прайс-лист'!$C$11:$C$310,MATCH(ROWS($A$16:A24),'Прайс-лист'!$T$11:$T$310,0)),"") | E24: =IFERROR(INDEX('Прайс-лист'!$E$11:$E$310,MATCH(ROWS($A$16:A24),'Прайс-лист'!$T$11:$T$310,0)),"") | F24: =IFERROR(INDEX('Прайс-лист'!$F$11:$F$310,MATCH(ROWS($A$16:A24),'Прайс-лист'!$T$11:$T$310,0)),"") | G24: =IFERROR(INDEX('Прайс-лист'!$R$11:$R$310,MATCH(ROWS($A$16:A24),'Прайс-лист'!$T$11:$T$310,0)),"") | H24: =IFERROR(INDEX('Прайс-лист'!$P$11:$P$310,MATCH(ROWS($A$16:A24),'Прайс-лист'!$T$11:$T$310,0)),"") | I24: =IFERROR(INDEX('Прайс-лист'!$S$11:$S$310,MATCH(ROWS($A$16:A24),'Прайс-лист'!$T$11:$T$310,0)),"") | J24: =IFERROR(INDEX('Прайс-лист'!$Q$11:$Q$310,MATCH(ROWS($A$16:A24),'Прайс-лист'!$T$11:$T$310,0)),"")
A25: =IFERROR(IF(INDEX('Прайс-лист'!$T$11:$T$310,MATCH(ROWS($A$16:A25),'Прайс-лист'!$T$11:$T$310,0))="","",ROWS($A$16:A25)),"") | B25: =IFERROR(INDEX('Прайс-лист'!$A$11:$A$310,MATCH(ROWS($A$16:A25),'Прайс-лист'!$T$11:$T$310,0)),"") | C25: =IFERROR(INDEX('Прайс-лист'!$B$11:$B$310,MATCH(ROWS($A$16:A25),'Прайс-лист'!$T$11:$T$310,0)),"") | D25: =IFERROR(INDEX('Прайс-лист'!$C$11:$C$310,MATCH(ROWS($A$16:A25),'Прайс-лист'!$T$11:$T$310,0)),"") | E25: =IFERROR(INDEX('Прайс-лист'!$E$11:$E$310,MATCH(ROWS($A$16:A25),'Прайс-лист'!$T$11:$T$310,0)),"") | F25: =IFERROR(INDEX('Прайс-лист'!$F$11:$F$310,MATCH(ROWS($A$16:A25),'Прайс-лист'!$T$11:$T$310,0)),"") | G25: =IFERROR(INDEX('Прайс-лист'!$R$11:$R$310,MATCH(ROWS($A$16:A25),'Прайс-лист'!$T$11:$T$310,0)),"") | H25: =IFERROR(INDEX('Прайс-лист'!$P$11:$P$310,MATCH(ROWS($A$16:A25),'Прайс-лист'!$T$11:$T$310,0)),"") | I25: =IFERROR(INDEX('Прайс-лист'!$S$11:$S$310,MATCH(ROWS($A$16:A25),'Прайс-лист'!$T$11:$T$310,0)),"") | J25: =IFERROR(INDEX('Прайс-лист'!$Q$11:$Q$310,MATCH(ROWS($A$16:A25),'Прайс-лист'!$T$11:$T$310,0)),"")
A26: =IFERROR(IF(INDEX('Прайс-лист'!$T$11:$T$310,MATCH(ROWS($A$16:A26),'Прайс-лист'!$T$11:$T$310,0))="","",ROWS($A$16:A26)),"") | B26: =IFERROR(INDEX('Прайс-лист'!$A$11:$A$310,MATCH(ROWS($A$16:A26),'Прайс-лист'!$T$11:$T$310,0)),"") | C26: =IFERROR(INDEX('Прайс-лист'!$B$11:$B$310,MATCH(ROWS($A$16:A26),'Прайс-лист'!$T$11:$T$310,0)),"") | D26: =IFERROR(INDEX('Прайс-лист'!$C$11:$C$310,MATCH(ROWS($A$16:A26),'Прайс-лист'!$T$11:$T$310,0)),"") | E26: =IFERROR(INDEX('Прайс-лист'!$E$11:$E$310,MATCH(ROWS($A$16:A26),'Прайс-лист'!$T$11:$T$310,0)),"") | F26: =IFERROR(INDEX('Прайс-лист'!$F$11:$F$310,MATCH(ROWS($A$16:A26),'Прайс-лист'!$T$11:$T$310,0)),"") | G26: =IFERROR(INDEX('Прайс-лист'!$R$11:$R$310,MATCH(ROWS($A$16:A26),'Прайс-лист'!$T$11:$T$310,0)),"") | H26: =IFERROR(INDEX('Прайс-лист'!$P$11:$P$310,MATCH(ROWS($A$16:A26),'Прайс-лист'!$T$11:$T$310,0)),"") | I26: =IFERROR(INDEX('Прайс-лист'!$S$11:$S$310,MATCH(ROWS($A$16:A26),'Прайс-лист'!$T$11:$T$310,0)),"") | J26: =IFERROR(INDEX('Прайс-лист'!$Q$11:$Q$310,MATCH(ROWS($A$16:A26),'Прайс-лист'!$T$11:$T$310,0)),"")
A27: =IFERROR(IF(INDEX('Прайс-лист'!$T$11:$T$310,MATCH(ROWS($A$16:A27),'Прайс-лист'!$T$11:$T$310,0))="","",ROWS($A$16:A27)),"") | B27: =IFERROR(INDEX('Прайс-лист'!$A$11:$A$310,MATCH(ROWS($A$16:A27),'Прайс-лист'!$T$11:$T$310,0)),"") | C27: =IFERROR(INDEX('Прайс-лист'!$B$11:$B$310,MATCH(ROWS($A$16:A27),'Прайс-лист'!$T$11:$T$310,0)),"") | D27: =IFERROR(INDEX('Прайс-лист'!$C$11:$C$310,MATCH(ROWS($A$16:A27),'Прайс-лист'!$T$11:$T$310,0)),"") | E27: =IFERROR(INDEX('Прайс-лист'!$E$11:$E$310,MATCH(ROWS($A$16:A27),'Прайс-лист'!$T$11:$T$310,0)),"") | F27: =IFERROR(INDEX('Прайс-лист'!$F$11:$F$310,MATCH(ROWS($A$16:A27),'Прайс-лист'!$T$11:$T$310,0)),"") | G27: =IFERROR(INDEX('Прайс-лист'!$R$11:$R$310,MATCH(ROWS($A$16:A27),'Прайс-лист'!$T$11:$T$310,0)),"") | H27: =IFERROR(INDEX('Прайс-лист'!$P$11:$P$310,MATCH(ROWS($A$16:A27),'Прайс-лист'!$T$11:$T$310,0)),"") | I27: =IFERROR(INDEX('Прайс-лист'!$S$11:$S$310,MATCH(ROWS($A$16:A27),'Прайс-лист'!$T$11:$T$310,0)),"") | J27: =IFERROR(INDEX('Прайс-лист'!$Q$11:$Q$310,MATCH(ROWS($A$16:A27),'Прайс-лист'!$T$11:$T$310,0)),"")
... A315: =IFERROR(IF(INDEX('Прайс-лист'!$T$11:$T$310,MATCH(ROWS($A$16:A315),'Прайс-лист'!$T$11:$T$310,0))="","",ROWS($A$16:A315)),"") | B315: =IFERROR(INDEX('Прайс-лист'!$A$11:$A$310,MATCH(ROWS($A$16:A315),'Прайс-лист'!$T$11:$T$310,0)),"") | C315: =IFERROR(INDEX('Прайс-лист'!$B$11:$B$310,MATCH(ROWS($A$16:A315),'Прайс-лист'!$T$11:$T$310,0)),"") | D315: =IFERROR(INDEX('Прайс-лист'!$C$11:$C$310,MATCH(ROWS($A$16:A315),'Прайс-лист'!$T$11:$T$310,0)),"") | E315: =IFERROR(INDEX('Прайс-лист'!$E$11:$E$310,MATCH(ROWS($A$16:A315),'Прайс-лист'!$T$11:$T$310,0)),"") | F315: =IFERROR(INDEX('Прайс-лист'!$F$11:$F$310,MATCH(ROWS($A$16:A315),'Прайс-лист'!$T$11:$T$310,0)),"") | G315: =IFERROR(INDEX('Прайс-лист'!$R$11:$R$310,MATCH(ROWS($A$16:A315),'Прайс-лист'!$T$11:$T$310,0)),"") | H315: =IFERROR(INDEX('Прайс-лист'!$P$11:$P$310,MATCH(ROWS($A$16:A315),'Прайс-лист'!$T$11:$T$310,0)),"") | I315: =IFERROR(INDEX('Прайс-лист'!$S$11:$S$310,MATCH(ROWS($A$16:A315),'Прайс-лист'!$T$11:$T$310,0)),"") | J315: =IFERROR(INDEX('Прайс-лист'!$Q$11:$Q$310,MATCH(ROWS($A$16:A315),'Прайс-лист'!$T$11:$T$310,0)),"")
A317: Цены, наличие товара, бонусы и специальные условия подтверждаются менеджером после проверки заказа. Прайс-лист не является публичной офертой.

Sheet Партнерская программа
A1: Партнерская программа регулярных закупок ПЧК
A2: Больше регулярности — больше партнерских преимуществ
A3: Мы обновили подход к работе с B2B-клиентами. Условия зависят от суммы заказа, регулярности закупок, роста объема, ширины ассортимента и платежной дисциплины.
A5: 1. Ценовые уровни
A6: Уровень | B6: Сумма заказа без НДС | C6: Что означает | D6: Индивидуальные условия
A7: Базовый | B7: от 20 000 до 50 000 ₽ | C7: стартовый заказ, базовые условия | D7: нет
A8: Опт | B8: от 50 000 ₽ | C8: стандартный оптовый уровень | D8: нет
A9: Опт+ | B9: от 150 000 ₽ | C9: улучшенный уровень для увеличенного заказа | D9: только как исключение
A10: Партнер | B10: от 300 000 ₽ | C10: расширенные партнерские преимущества | D10: частично возможны
A11: Ключевой партнер | B11: от 500 000 ₽ | C11: индивидуальные условия и возможность ретробонуса | D11: да
A13: 2. Как получить больше преимуществ
A14: Механика | B14: Что нужно сделать | C14: Что может получить клиент | D14: Комментарий
A15: Ценовые уровни | B15: увеличить сумму заказа | C15: перейти на более выгодный уровень | D15: уровень считается от суммы без НДС
A16: Бонус за регулярность | B16: закупать каждый месяц | C16: товарный бонус на следующий заказ | D16: регулярность считается от 20 000 ₽ без НДС
A17: Бонус за рост заказа | B17: увеличить сумму к прошлому заказу | C17: дополнительный товарный бонус | D17: расчет подтверждает менеджер
A18: Бонус за ширину ассортимента | B18: добавить больше SKU в заказ | C18: образцы, бонусные позиции, расширенные условия | D18: бонусы не автоматические
A19: Ретробонус | B19: выполнять согласованный план закупок | C19: бонус по итогам месяца или квартала | D19: для Партнера и Ключевого партнера
A21: 3. Бонус за регулярность
A22: Регулярность закупок | B22: Возможное преимущество | C22: Уточнение
A23: 2 месяца подряд | B23: образцы новинок или небольшой товарный бонус в следующий заказ | C23: заказы от 20 000 ₽ без НДС
A24: 3 месяца подряд | B24: повышенный товарный бонус в следующий заказ | C24: при отсутствии просрочки
A25: 6 месяцев подряд | B25: возможность индивидуальных условий и участия в ретробонусной программе | C25: согласуется индивидуально
A27: 4. Бонус за рост заказа
A28: Рост к предыдущему заказу | B28: Возможное преимущество | C28: Защита от некорректного расчета
A29: рост 15% | B29: +2% товарный бонус | C29: сравнение с предыдущей сопоставимой закупкой
A30: рост 25% | B30: +3% товарный бонус | C30: условия подтверждает менеджер
A31: рост 40%+ | B31: индивидуальный бонус или расширенные условия | C31: исключается сравнение со случайно малым заказом
A33: 5. Бонус за ширину ассортимента
A34: Количество SKU в заказе | B34: Возможное преимущество | C34: Коммерческий смысл
A35: от 10 SKU | B35: образцы новинок для тестирования | C35: расширяем будущую закупку
A36: от 20 SKU | B36: товарный бонус (+2-3% от суммы заказа) или расширенный набор образцов | C36: увеличивает долю ПЧК в ассортименте
A37: от 30 SKU | B37: повышенный товарный бонус (+4% от суммы заказа) или индивидуальное условие | C37: широкая матрица - залог хороших продаж
A39: 6. Ретробонус
A40: Уровень клиента | B40: Ретробонус | C40: Комментарий
A41: Базовый | B41: не применяется | C41: стартовый уровень
A42: Опт | B42: не применяется | C42: стандартный опт
A43: Опт+ | B43: возможен только как исключение | C43: по решению руководителя
A44: Партнер | B44: может быть согласован по итогам периода | C44: месяц или квартал
A45: Ключевой партнер | B45: может быть согласован индивидуально | C45: при регулярности и платежной дисциплине
A47: 7. Образцы и новинки
...

Sheet Условия работы
A1: Условия работы
A3: 1. Как оформить заказ | B3: Укажите количество на листе «Прайс-лист». Выбранные позиции автоматически попадут в «Бланк заказа». После этого отправьте файл менеджеру.
A4: 2. Минимальный заказ | B4: Минимальная сумма заказа — 20 000 ₽ без НДС. Ценовой уровень рассчитывается от суммы заказа без НДС.
A5: 3. Цены и НДС | B5: Цены в прайсе указаны без НДС. В бланке заказа НДС рассчитывается отдельной строкой. Итоговая сумма отображается с НДС.
A6: 4. Подтверждение заказа | B6: Цены, наличие, бонусы и специальные условия подтверждаются менеджером. Прайс-лист не является публичной офертой.
A7: 5. Оплата | B7: Для новых клиентов первая отгрузка осуществляется по 100% предоплате. Индивидуальные условия возможны после согласования и при отсутствии задолженности.
A8: 6. Отсрочка платежа | B8: Отсрочка может быть согласована индивидуально для регулярных клиентов с положительной историей оплат. При отсрочке бонусы могут быть ограничены.
A9: 7. Доставка | B9: Условия доставки согласуются с менеджером после подтверждения заказа. Возможны самовывоз, транспортная компания или иной согласованный способ.
A10: 8. Партнерские преимущества | B10: Бонусы, ретробонусы, образцы и специальные условия применяются после подтверждения менеджером и доступны только клиентам без просроченной задолженности.

Sheet Служебный лист
A1: Ставка НДС | B1: 0.22
A3: Уровень | B3: Порог без НДС | C3: Комментарий
A4: Базовый | B4: 20000 | C4: Минимальный заказ / базовый уровень
A5: Опт | B5: 50000 | C5: Стандартный оптовый уровень
A6: Опт+ | B6: 150000 | C6: Усиленные условия
A7: Партнер | B7: 300000 | C7: Частично индивидуальные условия
A8: Ключевой партнер | B8: 500000 | C8: Индивидуальные условия
A10: Кол-во SKU | B10: Подсказка
A11: 10+ | B11: Возможны образцы новинок
A12: 20+ | B12: Возможен бонус за ширину ассортимента
A13: 30+ | B13: Возможен расширенный бонус за ширину ассортимента
